Workbook

Sheet Raw_Data
A1: OrderID | B1: Date | C1: CustomerID | D1: Product | E1: Quantity | F1: UnitPrice | G1: ShippingAddress | H1: PaymentMethod | I1: OrderStatus | J1: TrackingNumber | K1: ItemsInCart | L1: CouponCode | M1: ReferralSource | N1: TotalPrice
A2: ORD200000 | B2: 44930 | C2: C72649 | D2: Monitor | E2: 5 | F2: 570.62 | G2: 928 Main St | H2: Debit Card | I2: Shipped | J2: TRK37947903 | K2: 7 | L2: SAVE10 | M2: Instagram | N2: 2853.1
A3: ORD200001 | B3: 45527 | C3: C75739 | D3: Phone | E3: 2 | F3: 151.35 | G3: 823 Main St | H3: Online | I3: Shipped | J3: TRK91186779 | K3: 3 | L3: SAVE10 | M3: Referral | N3: 302.7
A4: ORD200002 | B4: 45349 | C4: C81728 | D4: Tablet | E4: 5 | F4: 550.68 | G4: 512 Main St | H4: Credit Card | I4: Cancelled | J4: TRK42903982 | K4: 8 | L4: FREESHIP | M4: Email | N4: 2753.4
A5: ORD200003 | B5: 45214 | C5: C33540 | D5: Chair | E5: 1 | F5: 273.19 | G5: 275 Main St | H5: Debit Card | I5: Returned | J5: TRK62788070 | K5: 5 | L5: SAVE10 | M5: Facebook | N5: 273.19
A6: ORD200004 | B6: 45785 | C6: C81840 | D6: Printer | E6: 4 | F6: 626.01 | G6: 668 Main St | H6: Online | I6: Delivered | J6: TRK29241424 | K6: 8 | L6: SAVE10 | M6: Email | N6: 2504.04
A7: ORD200005 | B7: 45222 | C7: C37249 | D7: Phone | E7: 2 | F7: 245.86 | G7: 934 Main St | H7: Credit Card | I7: Shipped | J7: TRK72976927 | K7: 4 | L7: SAVE10 | M7: Instagram | N7: 491.72
A8: ORD200006 | B8: 45825 | C8: C83492 | D8: Laptop | E8: 1 | F8: 664.42 | G8: 986 Main St | H8: Gift Card | I8: Returned | J8: TRK96417362 | K8: 6 | L8: SAVE10 | M8: Facebook | N8: 664.42
A9: ORD200007 | B9: 45058 | C9: C41460 | D9: Monitor | E9: 5 | F9: 149.55 | G9: 706 Main St | H9: Cash | I9: Shipped | J9: TRK78809193 | K9: 9 | L9: FREESHIP | M9: Facebook | N9: 747.75
A10: ORD200008 | B10: 45749 | C10: C26817 | D10: Phone | E10: 2 | F10: 134.28 | G10: 904 Main St | H10: Gift Card | I10: Cancelled | J10: TRK61042692 | K10: 2 | M10: Email | N10: 268.56
A11: ORD200009 | B11: 45251 | C11: C31946 | D11: Desk | E11: 4 | F11: 509.38 | G11: 102 Main St | H11: Credit Card | I11: Shipped | J11: TRK33478363 | K11: 6 | L11: SAVE10 | M11: Google | N11: 2037.52
A12: ORD200010 | B12: 45289 | C12: C43443 | D12: Tablet | E12: 5 | F12: 625.97 | G12: 333 Main St | H12: Credit Card | I12: Returned | J12: TRK98859248 | K12: 9 | L12: WINTER15 | M12: Instagram | N12: 3129.85
A13: ORD200011 | B13: 45339 | C13: C93861 | D13: Monitor | E13: 3 | F13: 49.14 | G13: 831 Main St | H13: Online | I13: Returned | J13: TRK48234646 | K13: 7 | L13: SAVE10 | M13: Email | N13: 147.42
A14: ORD200012 | B14: 45580 | C14: C38785 | D14: Monitor | E14: 2 | F14: 180.5 | G14: 179 Main St | H14: Debit Card | I14: Pending | J14: TRK20419991 | K14: 6 | L14: FREESHIP | M14: Referral | N14: 361
A15: ORD200013 | B15: 45168 | C15: C88348 | D15: Laptop | E15: 3 | F15: 201.49 | G15: 903 Main St | H15: Credit Card | I15: Returned | J15: TRK81913874 | K15: 4 | L15: FREESHIP | M15: Facebook | N15: 604.47
A16: ORD200014 | B16: 45012 | C16: C98474 | D16: Tablet | E16: 2 | F16: 393.33 | G16: 980 Main St | H16: Debit Card | I16: Pending | J16: TRK79186539 | K16: 3 | L16: SAVE10 | M16: Instagram | N16: 786.66
A17: ORD200015 | B17: 45124 | C17: C39416 | D17: Printer | E17: 1 | F17: 473.96 | G17: 942 Main St | H17: Cash | I17: Delivered | J17: TRK54930938 | K17: 3 | M17: Google | N17: 473.96
A18: ORD200016 | B18: 44950 | C18: C28976 | D18: Printer | E18: 2 | F18: 533.81 | G18: 914 Main St | H18: Credit Card | I18: Pending | J18: TRK13194259 | K18: 3 | L18: FREESHIP | M18: Email | N18: 1067.62
A19: ORD200017 | B19: 45353 | C19: C60672 | D19: Tablet | E19: 1 | F19: 423.4 | G19: 382 Main St | H19: Debit Card | I19: Shipped | J19: TRK11972116 | K19: 3 | M19: Referral | N19: 423.4
A20: ORD200018 | B20: 45742 | C20: C84329 | D20: Desk | E20: 1 | F20: 431.44 | G20: 891 Main St | H20: Gift Card | I20: Pending | J20: TRK65191045 | K20: 3 | L20: SAVE10 | M20: Facebook | N20: 431.44
A21: ORD200019 | B21: 44949 | C21: C14552 | D21: Monitor | E21: 5 | F21: 224 | G21: 273 Main St | H21: Cash | I21: Returned | J21: TRK59101365 | K21: 9 | L21: SAVE10 | M21: Google | N21: 1120
A22: ORD200020 | B22: 45054 | C22: C54829 | D22: Chair | E22: 5 | F22: 62.51 | G22: 587 Main St | H22: Cash | I22: Pending | J22: TRK16718651 | K22: 9 | L22: WINTER15 | M22: Instagram | N22: 312.55
A23: ORD200021 | B23: 45613 | C23: C99023 | D23: Monitor | E23: 4 | F23: 342.95 | G23: 569 Main St | H23: Cash | I23: Delivered | J23: TRK52646983 | K23: 6 | M23: Google | N23: 1371.8
A24: ORD200022 | B24: 44955 | C24: C34416 | D24: Monitor | E24: 2 | F24: 49.62 | G24: 633 Main St | H24: Online | I24: Pending | J24: TRK75937350 | K24: 2 | L24: SAVE10 | M24: Google | N24: 99.24
A25: ORD200023 | B25: 45756 | C25: C42372 | D25: Phone | E25: 4 | F25: 273.25 | G25: 755 Main St | H25: Debit Card | I25: Cancelled | J25: TRK36168083 | K25: 5 | L25: FREESHIP | M25: Referral | N25: 1093
A26: ORD200024 | B26: 45595 | C26: C17470 | D26: Laptop | E26: 2 | F26: 230.95 | G26: 956 Main St | H26: Online | I26: Delivered | J26: TRK28775057 | K26: 3 | L26: WINTER15 | M26: Referral | N26: 461.9
A27: ORD200025 | B27: 45497 | C27: C42577 | D27: Monitor | E27: 1 | F27: 399.98 | G27: 709 Main St | H27: Debit Card | I27: Delivered | J27: TRK69423327 | K27: 3 | L27: WINTER15 | M27: Email | N27: 399.98
A28: ORD200026 | B28: 45357 | C28: C21944 | D28: Laptop | E28: 5 | F28: 59.55 | G28: 296 Main St | H28: Online | I28: Delivered | J28: TRK80276812 | K28: 6 | M28: Referral | N28: 297.75
A29: ORD200027 | B29: 45344 | C29: C97593 | D29: Printer | E29: 1 | F29: 472.74 | G29: 881 Main St | H29: Online | I29: Shipped | J29: TRK89117573 | K29: 6 | L29: WINTER15 | M29: Google | N29: 472.74
A30: ORD200028 | B30: 45251 | C30: C59823 | D30: Phone | E30: 4 | F30: 160.07 | G30: 568 Main St | H30: Online | I30: Pending | J30: TRK65895539 | K30: 5 | M30: Email | N30: 640.28
A31: ORD200029 | B31: 45555 | C31: C33260 | D31: Desk | E31: 3 | F31: 423.53 | G31: 930 Main St | H31: Credit Card | I31: Delivered | J31: TRK59744090 | K31: 6 | L31: SAVE10 | M31: Referral | N31: 1270.59
A32: ORD200030 | B32: 45738 | C32: C44267 | D32: Monitor | E32: 2 | F32: 426.7 | G32: 895 Main St | H32: Online | I32: Pending | J32: TRK54751444 | K32: 5 | L32: SAVE10 | M32: Referral | N32: 853.4
A33: ORD200031 | B33: 45107 | C33: C26445 | D33: Chair | E33: 3 | F33: 500.08 | G33: 996 Main St | H33: Debit Card | I33: Returned | J33: TRK31229981 | K33: 6 | M33: Facebook | N33: 1500.24
A34: ORD200032 | B34: 45047 | C34: C12388 | D34: Tablet | E34: 5 | F34: 536.72 | G34: 830 Main St | H34: Cash | I34: Delivered | J34: TRK99261395 | K34: 10 | M34: Email | N34: 2683.6
A35: ORD200033 | B35: 45082 | C35: C52184 | D35: Chair | E35: 1 | F35: 162.77 | G35: 912 Main St | H35: Online | I35: Cancelled | J35: TRK73312471 | K35: 4 | L35: WINTER15 | M35: Facebook | N35: 162.77
A36: ORD200034 | B36: 44933 | C36: C67195 | D36: Chair | E36: 4 | F36: 576.52 | G36: 926 Main St | H36: Credit Card | I36: Pending | J36: TRK55467915 | K36: 5 | L36: WINTER15 | M36: Facebook | N36: 2306.08
A37: ORD200035 | B37: 45633 | C37: C50304 | D37: Monitor | E37: 2 | F37: 465.15 | G37: 128 Main St | H37: Online | I37: Shipped | J37: TRK46850888 | K37: 2 | L37: SAVE10 | M37: Facebook | N37: 930.3
A38: ORD200036 | B38: 45785 | C38: C59337 | D38: Laptop | E38: 2 | F38: 534.43 | G38: 465 Main St | H38: Debit Card | I38: Pending | J38: TRK50961250 | K38: 5 | M38: Facebook | N38: 1068.86
A39: ORD200037 | B39: 45579 | C39: C10054 | D39: Laptop | E39: 2 | F39: 76.74 | G39: 409 Main St | H39: Cash | I39: Returned | J39: TRK94005261 | K39: 7 | L39: SAVE10 | M39: Instagram | N39: 153.48
A40: ORD200038 | B40: 45645 | C40: C15924 | D40: Laptop | E40: 1 | F40: 245.89 | G40: 549 Main St | H40: Debit Card | I40: Delivered | J40: TRK14835975 | K40: 3 | L40: SAVE10 | M40: Google | N40: 245.89
...

Sheet Cleaned_Data
A1: OrderID | B1: Date | C1: CustomerID | D1: Product | E1: Quantity | F1: UnitPrice | G1: ShippingAddress | H1: PaymentMethod | I1: OrderStatus | J1: TrackingNumber | K1: ItemsInCart | L1: CouponCode | M1: ReferralSource | N1: TotalPrice | O1: Duplicate_OrderID_Check | P1: Duplicate_Tracking_Check | Q1: CouponCode_Was_Missing | R1: Date_Valid_Check
A2: =TRIM(Raw_Data!A2) | B2: =Raw_Data!B2 | C2: =TRIM(Raw_Data!C2) | D2: =PROPER(TRIM(Raw_Data!D2)) | E2: =Raw_Data!E2 | F2: =ROUND(Raw_Data!F2,2) | G2: =PROPER(TRIM(Raw_Data!G2)) | H2: =PROPER(TRIM(Raw_Data!H2)) | I2: =PROPER(TRIM(Raw_Data!I2)) | J2: =TRIM(Raw_Data!J2) | K2: =Raw_Data!K2 | L2: =IF(TRIM(Raw_Data!L2)="","No Coupon",TRIM(Raw_Data!L2)) | M2: =PROPER(TRIM(Raw_Data!M2)) | N2: =ROUND(Raw_Data!N2,2) | O2: =IF(COUNTIF($A$2:$A$1201,A2)>1,"DUPLICATE","Unique") | P2: =IF(COUNTIF($J$2:$J$1201,J2)>1,"DUPLICATE","Unique") | Q2: =IF(TRIM(Raw_Data!L2)="","Yes","No") | R2: =IF(ISNUMBER(B2),"Valid","INVALID")
A3: =TRIM(Raw_Data!A3) | B3: =Raw_Data!B3 | C3: =TRIM(Raw_Data!C3) | D3: =PROPER(TRIM(Raw_Data!D3)) | E3: =Raw_Data!E3 | F3: =ROUND(Raw_Data!F3,2) | G3: =PROPER(TRIM(Raw_Data!G3)) | H3: =PROPER(TRIM(Raw_Data!H3)) | I3: =PROPER(TRIM(Raw_Data!I3)) | J3: =TRIM(Raw_Data!J3) | K3: =Raw_Data!K3 | L3: =IF(TRIM(Raw_Data!L3)="","No Coupon",TRIM(Raw_Data!L3)) | M3: =PROPER(TRIM(Raw_Data!M3)) | N3: =ROUND(Raw_Data!N3,2) | O3: =IF(COUNTIF($A$2:$A$1201,A3)>1,"DUPLICATE","Unique") | P3: =IF(COUNTIF($J$2:$J$1201,J3)>1,"DUPLICATE","Unique") | Q3: =IF(TRIM(Raw_Data!L3)="","Yes","No") | R3: =IF(ISNUMBER(B3),"Valid","INVALID")
A4: =TRIM(Raw_Data!A4) | B4: =Raw_Data!B4 | C4: =TRIM(Raw_Data!C4) | D4: =PROPER(TRIM(Raw_Data!D4)) | E4: =Raw_Data!E4 | F4: =ROUND(Raw_Data!F4,2) | G4: =PROPER(TRIM(Raw_Data!G4)) | H4: =PROPER(TRIM(Raw_Data!H4)) | I4: =PROPER(TRIM(Raw_Data!I4)) | J4: =TRIM(Raw_Data!J4) | K4: =Raw_Data!K4 | L4: =IF(TRIM(Raw_Data!L4)="","No Coupon",TRIM(Raw_Data!L4)) | M4: =PROPER(TRIM(Raw_Data!M4)) | N4: =ROUND(Raw_Data!N4,2) | O4: =IF(COUNTIF($A$2:$A$1201,A4)>1,"DUPLICATE","Unique") | P4: =IF(COUNTIF($J$2:$J$1201,J4)>1,"DUPLICATE","Unique") | Q4: =IF(TRIM(Raw_Data!L4)="","Yes","No") | R4: =IF(ISNUMBER(B4),"Valid","INVALID")
A5: =TRIM(Raw_Data!A5) | B5: =Raw_Data!B5 | C5: =TRIM(Raw_Data!C5) | D5: =PROPER(TRIM(Raw_Data!D5)) | E5: =Raw_Data!E5 | F5: =ROUND(Raw_Data!F5,2) | G5: =PROPER(TRIM(Raw_Data!G5)) | H5: =PROPER(TRIM(Raw_Data!H5)) | I5: =PROPER(TRIM(Raw_Data!I5)) | J5: =TRIM(Raw_Data!J5) | K5: =Raw_Data!K5 | L5: =IF(TRIM(Raw_Data!L5)="","No Coupon",TRIM(Raw_Data!L5)) | M5: =PROPER(TRIM(Raw_Data!M5)) | N5: =ROUND(Raw_Data!N5,2) | O5: =IF(COUNTIF($A$2:$A$1201,A5)>1,"DUPLICATE","Unique") | P5: =IF(COUNTIF($J$2:$J$1201,J5)>1,"DUPLICATE","Unique") | Q5: =IF(TRIM(Raw_Data!L5)="","Yes","No") | R5: =IF(ISNUMBER(B5),"Valid","INVALID")
A6: =TRIM(Raw_Data!A6) | B6: =Raw_Data!B6 | C6: =TRIM(Raw_Data!C6) | D6: =PROPER(TRIM(Raw_Data!D6)) | E6: =Raw_Data!E6 | F6: =ROUND(Raw_Data!F6,2) | G6: =PROPER(TRIM(Raw_Data!G6)) | H6: =PROPER(TRIM(Raw_Data!H6)) | I6: =PROPER(TRIM(Raw_Data!I6)) | J6: =TRIM(Raw_Data!J6) | K6: =Raw_Data!K6 | L6: =IF(TRIM(Raw_Data!L6)="","No Coupon",TRIM(Raw_Data!L6)) | M6: =PROPER(TRIM(Raw_Data!M6)) | N6: =ROUND(Raw_Data!N6,2) | O6: =IF(COUNTIF($A$2:$A$1201,A6)>1,"DUPLICATE","Unique") | P6: =IF(COUNTIF($J$2:$J$1201,J6)>1,"DUPLICATE","Unique") | Q6: =IF(TRIM(Raw_Data!L6)="","Yes","No") | R6: =IF(ISNUMBER(B6),"Valid","INVALID")
A7: =TRIM(Raw_Data!A7) | B7: =Raw_Data!B7 | C7: =TRIM(Raw_Data!C7) | D7: =PROPER(TRIM(Raw_Data!D7)) | E7: =Raw_Data!E7 | F7: =ROUND(Raw_Data!F7,2) | G7: =PROPER(TRIM(Raw_Data!G7)) | H7: =PROPER(TRIM(Raw_Data!H7)) | I7: =PROPER(TRIM(Raw_Data!I7)) | J7: =TRIM(Raw_Data!J7) | K7: =Raw_Data!K7 | L7: =IF(TRIM(Raw_Data!L7)="","No Coupon",TRIM(Raw_Data!L7)) | M7: =PROPER(TRIM(Raw_Data!M7)) | N7: =ROUND(Raw_Data!N7,2) | O7: =IF(COUNTIF($A$2:$A$1201,A7)>1,"DUPLICATE","Unique") | P7: =IF(COUNTIF($J$2:$J$1201,J7)>1,"DUPLICATE","Unique") | Q7: =IF(TRIM(Raw_Data!L7)="","Yes","No") | R7: =IF(ISNUMBER(B7),"Valid","INVALID")
A8: =TRIM(Raw_Data!A8) | B8: =Raw_Data!B8 | C8: =TRIM(Raw_Data!C8) | D8: =PROPER(TRIM(Raw_Data!D8)) | E8: =Raw_Data!E8 | F8: =ROUND(Raw_Data!F8,2) | G8: =PROPER(TRIM(Raw_Data!G8)) | H8: =PROPER(TRIM(Raw_Data!H8)) | I8: =PROPER(TRIM(Raw_Data!I8)) | J8: =TRIM(Raw_Data!J8) | K8: =Raw_Data!K8 | L8: =IF(TRIM(Raw_Data!L8)="","No Coupon",TRIM(Raw_Data!L8)) | M8: =PROPER(TRIM(Raw_Data!M8)) | N8: =ROUND(Raw_Data!N8,2) | O8: =IF(COUNTIF($A$2:$A$1201,A8)>1,"DUPLICATE","Unique") | P8: =IF(COUNTIF($J$2:$J$1201,J8)>1,"DUPLICATE","Unique") | Q8: =IF(TRIM(Raw_Data!L8)="","Yes","No") | R8: =IF(ISNUMBER(B8),"Valid","INVALID")
A9: =TRIM(Raw_Data!A9) | B9: =Raw_Data!B9 | C9: =TRIM(Raw_Data!C9) | D9: =PROPER(TRIM(Raw_Data!D9)) | E9: =Raw_Data!E9 | F9: =ROUND(Raw_Data!F9,2) | G9: =PROPER(TRIM(Raw_Data!G9)) | H9: =PROPER(TRIM(Raw_Data!H9)) | I9: =PROPER(TRIM(Raw_Data!I9)) | J9: =TRIM(Raw_Data!J9) | K9: =Raw_Data!K9 | L9: =IF(TRIM(Raw_Data!L9)="","No Coupon",TRIM(Raw_Data!L9)) | M9: =PROPER(TRIM(Raw_Data!M9)) | N9: =ROUND(Raw_Data!N9,2) | O9: =IF(COUNTIF($A$2:$A$1201,A9)>1,"DUPLICATE","Unique") | P9: =IF(COUNTIF($J$2:$J$1201,J9)>1,"DUPLICATE","Unique") | Q9: =IF(TRIM(Raw_Data!L9)="","Yes","No") | R9: =IF(ISNUMBER(B9),"Valid","INVALID")
A10: =TRIM(Raw_Data!A10) | B10: =Raw_Data!B10 | C10: =TRIM(Raw_Data!C10) | D10: =PROPER(TRIM(Raw_Data!D10)) | E10: =Raw_Data!E10 | F10: =ROUND(Raw_Data!F10,2) | G10: =PROPER(TRIM(Raw_Data!G10)) | H10: =PROPER(TRIM(Raw_Data!H10)) | I10: =PROPER(TRIM(Raw_Data!I10)) | J10: =TRIM(Raw_Data!J10) | K10: =Raw_Data!K10 | L10: =IF(TRIM(Raw_Data!L10)="","No Coupon",TRIM(Raw_Data!L10)) | M10: =PROPER(TRIM(Raw_Data!M10)) | N10: =ROUND(Raw_Data!N10,2) | O10: =IF(COUNTIF($A$2:$A$1201,A10)>1,"DUPLICATE","Unique") | P10: =IF(COUNTIF($J$2:$J$1201,J10)>1,"DUPLICATE","Unique") | Q10: =IF(TRIM(Raw_Data!L10)="","Yes","No") | R10: =IF(ISNUMBER(B10),"Valid","INVALID")
A11: =TRIM(Raw_Data!A11) | B11: =Raw_Data!B11 | C11: =TRIM(Raw_Data!C11) | D11: =PROPER(TRIM(Raw_Data!D11)) | E11: =Raw_Data!E11 | F11: =ROUND(Raw_Data!F11,2) | G11: =PROPER(TRIM(Raw_Data!G11)) | H11: =PROPER(TRIM(Raw_Data!H11)) | I11: =PROPER(TRIM(Raw_Data!I11)) | J11: =TRIM(Raw_Data!J11) | K11: =Raw_Data!K11 | L11: =IF(TRIM(Raw_Data!L11)="","No Coupon",TRIM(Raw_Data!L11)) | M11: =PROPER(TRIM(Raw_Data!M11)) | N11: =ROUND(Raw_Data!N11,2) | O11: =IF(COUNTIF($A$2:$A$1201,A11)>1,"DUPLICATE","Unique") | P11: =IF(COUNTIF($J$2:$J$1201,J11)>1,"DUPLICATE","Unique") | Q11: =IF(TRIM(Raw_Data!L11)="","Yes","No") | R11: =IF(ISNUMBER(B11),"Valid","INVALID")
A12: =TRIM(Raw_Data!A12) | B12: =Raw_Data!B12 | C12: =TRIM(Raw_Data!C12) | D12: =PROPER(TRIM(Raw_Data!D12)) | E12: =Raw_Data!E12 | F12: =ROUND(Raw_Data!F12,2) | G12: =PROPER(TRIM(Raw_Data!G12)) | H12: =PROPER(TRIM(Raw_Data!H12)) | I12: =PROPER(TRIM(Raw_Data!I12)) | J12: =TRIM(Raw_Data!J12) | K12: =Raw_Data!K12 | L12: =IF(TRIM(Raw_Data!L12)="","No Coupon",TRIM(Raw_Data!L12)) | M12: =PROPER(TRIM(Raw_Data!M12)) | N12: =ROUND(Raw_Data!N12,2) | O12: =IF(COUNTIF($A$2:$A$1201,A12)>1,"DUPLICATE","Unique") | P12: =IF(COUNTIF($J$2:$J$1201,J12)>1,"DUPLICATE","Unique") | Q12: =IF(TRIM(Raw_Data!L12)="","Yes","No") | R12: =IF(ISNUMBER(B12),"Valid","INVALID")
A13: =TRIM(Raw_Data!A13) | B13: =Raw_Data!B13 | C13: =TRIM(Raw_Data!C13) | D13: =PROPER(TRIM(Raw_Data!D13)) | E13: =Raw_Data!E13 | F13: =ROUND(Raw_Data!F13,2) | G13: =PROPER(TRIM(Raw_Data!G13)) | H13: =PROPER(TRIM(Raw_Data!H13)) | I13: =PROPER(TRIM(Raw_Data!I13)) | J13: =TRIM(Raw_Data!J13) | K13: =Raw_Data!K13 | L13: =IF(TRIM(Raw_Data!L13)="","No Coupon",TRIM(Raw_Data!L13)) | M13: =PROPER(TRIM(Raw_Data!M13)) | N13: =ROUND(Raw_Data!N13,2) | O13: =IF(COUNTIF($A$2:$A$1201,A13)>1,"DUPLICATE","Unique") | P13: =IF(COUNTIF($J$2:$J$1201,J13)>1,"DUPLICATE","Unique") | Q13: =IF(TRIM(Raw_Data!L13)="","Yes","No") | R13: =IF(ISNUMBER(B13),"Valid","INVALID")
... A1201: =TRIM(Raw_Data!A1201) | B1201: =Raw_Data!B1201 | C1201: =TRIM(Raw_Data!C1201) | D1201: =PROPER(TRIM(Raw_Data!D1201)) | E1201: =Raw_Data!E1201 | F1201: =ROUND(Raw_Data!F1201,2) | G1201: =PROPER(TRIM(Raw_Data!G1201)) | H1201: =PROPER(TRIM(Raw_Data!H1201)) | I1201: =PROPER(TRIM(Raw_Data!I1201)) | J1201: =TRIM(Raw_Data!J1201) | K1201: =Raw_Data!K1201 | L1201: =IF(TRIM(Raw_Data!L1201)="","No Coupon",TRIM(Raw_Data!L1201)) | M1201: =PROPER(TRIM(Raw_Data!M1201)) | N1201: =ROUND(Raw_Data!N1201,2) | O1201: =IF(COUNTIF($A$2:$A$1201,A1201)>1,"DUPLICATE","Unique") | P1201: =IF(COUNTIF($J$2:$J$1201,J1201)>1,"DUPLICATE","Unique") | Q1201: =IF(TRIM(Raw_Data!L1201)="","Yes","No") | R1201: =IF(ISNUMBER(B1201),"Valid","INVALID")

Sheet Verification_Gate
A1: Check | B1: Result | C1: Pass Threshold
A2: Duplicate OrderID count | B2: =SUMPRODUCT((COUNTIF(Cleaned_Data!A2:A1201,Cleaned_Data!A2:A1201)>1)*1) | C2: 0
A3: Duplicate TrackingNumber count | B3: =SUMPRODUCT((COUNTIF(Cleaned_Data!J2:J1201,Cleaned_Data!J2:J1201)>1)*1) | C3: 0
A4: Invalid / non-date Date cells | B4: =SUMPRODUCT(--NOT(ISNUMBER(Cleaned_Data!B2:B1201))) | C4: 0
A5: Remaining blank CouponCode cells (post-fix) | B5: =COUNTBLANK(Cleaned_Data!L2:L1201) | C5: 0
A6: VERDICT | B6: =IF(SUM(B2:B5)=0,"PASS - 0% Error Rate","FAIL - Review Required")

Sheet Change_Log
A1: Change ID | B1: Description | C1: Impact | D1: Status
A2: CR001 | B2: Filled missing CouponCode values with explicit label 'No Coupon' (not mean/mode, since absence is meaningful, not random) | C2: =COUNTBLANK(Raw_Data!L2:L1201)&" of "&1200&" records ("&TEXT(COUNTBLANK(Raw_Data!L2:L1201)/1200,"0.0%")&")" | D2: Resolved
A3: CR002 | B3: Audited OrderID and TrackingNumber for duplicates via COUNTIF (Excel equivalent of GROUP BY ... HAVING COUNT(*) > 1) | C3: ="Duplicate OrderIDs: "&Verification_Gate!B2&" | Duplicate TrackingNumbers: "&Verification_Gate!B3 | D3: Resolved
A4: CR003 | B4: Trimmed whitespace and Proper-cased free-text fields (Product, PaymentMethod, OrderStatus, ShippingAddress, ReferralSource); ID/code columns left case-untouched | C4: ="Applied across "&1200&" records on 5 columns" | D4: Resolved
A5: CR004 | B5: Applied ROUND(...,2) and a fixed 0.00 number format to UnitPrice/TotalPrice so every value displays exactly 2 decimal places (raw export had 0, 1, or 2 decimals inconsistently) | C5: =1200&" UnitPrice and "&1200&" TotalPrice cells standardized to 2-decimal precision" | D5: Resolved
A6: CR005 | B6: Validated Date column as true Excel date type and applied ISO 8601 (yyyy-mm-dd) display format | C6: ="Invalid dates found: "&Verification_Gate!B4 | D6: Resolved
